Workbook

Sheet FilterCriteria
A1: No | B1: Title | C1: Description
A2: 1 | B2: The source provides a downloadable data file | C2: A data file is required to verify the extracted elements by mapping each column to the corresponding element.
A3: 2 | B3: The data are generated by IoT devices | C3: Only data generated by IoT devices are required, in line with the goal of verifying the common IoT schema.
A4: 3 | B4: The source includes a data description | C4: A data description is essential for understanding the context and structure of the data file. It should specify the sensors or sensor types used, the objects measured, and definitions of all data fields, thereby ensuring accurate interpretation and effective use of the dataset.

Sheet SearchResults
A1: Repository | B1: Sublink | C1: Key Words | D1: FIlters | E1: Date | F1: ResultCounts | G1: FilteredCounts | H1: Note
A2: Generalist data repository | B2: Dryad Digital Repository | C2: IoT | E2: 45893 | F2: 9 | G2: 3
A3: Generalist data repository | B3: Dryad Digital Repository | C3: "sensor dataset" | E3: 45903 | F3: 3 | G3: 3
A4: Generalist data repository | B4: Zenodo | C4: "sensor dataset" | D4: Open, Dataset | E4: 45903 | F4: 35 | G4: =COUNTIF(Table2[Sublink],SearchResults!$B4) -> 30
A5: Generalist data repository | B5: Harvard Dataverse | C5: "sensor dataset" | D5: Datasets | E5: 45903 | F5: 5 | G5: =COUNTIF(Table2[Sublink],SearchResults!$B5) -> 2
A6: Generalist data repository | B6: Open Science Framework | C6: "sensor dataset" | E6: 45903 | F6: 1 | G6: =COUNTIF(Table2[Sublink],SearchResults!$B6) -> 1
A7: Generalist data repository | B7: FAIRsharing.org - Movebank Data Repository | C7: "sensor dataset" | E7: 45904 | F7: 0 | G7: 0
A8: Generalist data repository | B8: FAIRsharing.org - Norwegian Polar Data Centre | C8: sensor dataset | E8: 45904 | F8: 28 | G8: =COUNTIF(Table2[Sublink],SearchResults!$B8) -> 26
A9: Generalist data repository | B9: re3data.org. | C9: sensor dataset | E9: 45904 | F9: 9 | G9: 0 | H9: No data files can be found, only description
A10: Generalist data repository | B10: figshare | C10: "sensor dataset" | D10: dataset | E10: 45904 | F10: 14 | G10: =COUNTIF(Table2[Sublink],SearchResults!$B10) -> 5
A11: Total | F11: =SUM(F2:F10) -> 104 | G11: =SUM(G2:G10) -> 70

Sheet FilteredResults
A1: Sublink | B1: Title | C1: Link
A2: Dryad Digital Repository | B2: FlyPaw: Optimized route planning for scientific UAV missions | C2: https://datadryad.org/dataset/doi:10.5061/dryad.0gb5mkm8d
A3: Dryad Digital Repository | B3: LoRaWAN gateway performance and vehicle tracking data in AERPAW testbed | C3: https://datadryad.org/dataset/doi:10.5061/dryad.w0vt4b939#readme
A4: Dryad Digital Repository | B4: Aerial Measurements from Outdoor 2.4GHz 802.15.4 Network | C4: https://datadryad.org/dataset/doi:10.25349/D9KS3W
A5: Dryad Digital Repository | B5: A multi-modal sensor dataset for continuous stress detection of nurses in a hospital | C5: https://datadryad.org/dataset/doi:10.5061/dryad.5hqbzkh6f#usage
A6: Dryad Digital Repository | B6: A multi-sensor gait dataset collected under non-standardized dual-task conditions | C6: https://datadryad.org/dataset/doi:10.5061/dryad.2rbnzs7z3#readme
A7: Dryad Digital Repository | B7: mRI: multi-modal 3d human pose estimation dataset using mmwave, rgb-d, and inertial sensors | C7: https://datadryad.org/dataset/doi:10.5061/dryad.9ghx3ffpp
A8: Zenodo | B8: SIMPaCT Soil Moisture Sensor Dataset | C8: https://zenodo.org/records/16811020
A9: Zenodo | B9: Drone onboard multi-modal sensor dataset | C9: https://zenodo.org/records/7643456
A10: Zenodo | B10: Multimodal Sensor Dataset from Wood/Forest Environment - Adões | C10: https://zenodo.org/records/13757335
A11: Zenodo | B11: Multimodal Sensor Dataset from Wood/Forest Environment - iParque | C11: https://zenodo.org/records/13757084
A12: Zenodo | B12: Multi-Sensor Dataset From Android Smart Devices | C12: https://zenodo.org/records/8340005
... A71: figshare | B71: Data from: A field-scale sensor network data set for monitoring and modeling the spatial and temporal variation of soil moisture in a dryland agricultural field | C71: https://figshare.com/articles/dataset/Data_from_A_field-scale_sensor_network_data_set_for_monitoring_and_modeling_the_spatial_and_temporal_variation_of_soil_moisture_in_a_dryland_agricultural_field/24852273?file=44335805

Sheet DatasetInfo
G1: Data Schema Extracted from SOSA/SSN
A2: DatasetNo | B2: Industry | C2: Topic | D2: Content | E2: SourcePlatform | F2: Website | G2: IoT Device | H2: Sample | I2: FeatureOfInterest | J2: Property | K2: Result | L2: Platform | M2: Deployment | N2: resultTime
A3: 1 | B3: Communication | C3: Optimized route planning for scientific UAV missions | D3: It integrates UAV telemetry with wireless network performance (srsRAN SDR + iperf) and flight state logs to support experiments in optimized UAV route planning. | E3: Dryad Digital Repository | F3: https://datadryad.org/dataset/doi:10.5061/dryad.0gb5mkm8d | G3: 1 | H3: 1 | I3: 1 | J3: 1 | K3: 1 | M3: 1 | N3: 1
A4: 2 | B4: Communication | C4: LoRaWAN gateway performance | D4: It evaluates the performance of LoRaWAN gateways by analyzing received telemetry data from a moving vehicle (i.e., helikite). Key metrics include Received Signal Strength Indicator (RSSI), Signal-to-Noise Ratio (SNR), transmission timestamps, and geographic data. | E4: Dryad Digital Repository | F4: https://datadryad.org/dataset/doi:10.5061/dryad.w0vt4b939#readme | G4: 1 | I4: 1 | J4: 1 | K4: 1 | M4: 1 | N4: 1
A5: 3 | B5: Communication | C5: Aerial Measurements from Outdoor 2.4GHz 802.15.4 Network | D5: Signal strength and reception rate of packets | E5: Dryad Digital Repository | F5: https://datadryad.org/dataset/doi:10.25349/D9KS3W | G5: 1 | I5: 1 | J5: 1 | K5: 1 | M5: 1 | N5: 1
A6: 4 | B6: Health | C6: Stress detection using wearable biometric signals and contextual surveys | D6: A dataset of 15 nurses collected during the COVID-19 outbreak in a natural hospital work environment. It includes continuous biometric sensor signals (EDA, HR, TEMP, IBI, BVP, ACC) from wearable devices, contextual event tagging, and periodic smartphone-based stress surveys with stress levels and contributing factors. | E6: Dryad Digital Repository | F6: https://datadryad.org/dataset/doi:10.5061/dryad.5hqbzkh6f#usage | G6: 1 | H6: 1 | I6: 1 | J6: 1 | K6: 1 | L6: 1 | M6: 1 | N6: 1
A7: 5 | B7: Health | C7: Human gait under non-standardized dual-task walking (normal, holding a water cup, texting, browsing the web), with repeated sessions and segmented phases (go, back, turn) | D7: 23 participants × 2 sessions × 4 tasks. Folders: Raw (MOCAP, Kinect, IMU, Timestamp), Processed (segmented by sensor, session, phase, task), and Parameters (spatio-temporal & kinematic features). Demographics provided; data de-identified | E7: Dryad Digital Repository | F7: https://datadryad.org/dataset/doi:10.5061/dryad.2rbnzs7z3#readme | G7: 1 | H7: 1 | I7: 1 | J7: 1 | K7: 1 | L7: 1 | M7: 1 | N7: 1
A8: 6 | B8: Health | C8: Multi-modal 3D human pose estimation dataset, fusing radar, IMU, and RGB-D data across 20 subjects | D8: 40 RGB videos, raw data: imu, radar, annotations, timestamps, video labels. | E8: Dryad Digital Repository | F8: https://datadryad.org/dataset/doi:10.5061/dryad.9ghx3ffpp | G8: 1 | H8: 1 | I8: 1 | J8: 1 | K8: 1 | M8: 1 | N8: 1
A9: 7 | B9: Agriculture | C9: Soil moisture monitoring dataset, used to study mutual-information-based virtual sensor prediction | D9: VWC readings | E9: Zenodo | F9: https://zenodo.org/records/16811020 | G9: 1 | I9: 1 | J9: 1 | K9: 1 | M9: 1 | N9: 1
A10: 8 | B10: Aerospace | C10: Drone flight telemetry and state classification. Trajectory prediction and multi-task learning with sensor data | D10: Time series dataset of multiple drone flights using a DJI Matrice 300 (M300). Includes unique flight IDs, timestamps, position, orientation, velocity, acceleration, battery status, payload type, weather conditions, and drone states (IDLE_HOVER, ASCEND, TURN, HMSL, DESCEND). Designed for trajectory prediction, classification, and UAV control research under different flight patterns (triangular, square, polygonal, random). | E10: Zenodo | F10: https://zenodo.org/records/7643456 | G10: 1 | H10: 1 | I10: 1 | J10: 1 | K10: 1 | M10: 1 | N10: 1
A11: 9 | B11: Environment | C11: Adões - Multimodal robotic sensor dataset in a forest scenario. Trajectory recording, perception, and localization for robotic research. | D11: Contains synchronized multi-sensor recordings (LiDAR, stereo + RGB-D cameras, IMU, GNSS) | E11: Zenodo | F11: https://zenodo.org/records/13757335 | G11: 1 | I11: 1 | J11: 1 | K11: 1 | L11: 1 | M11: 1 | N11: 1
A12: 10 | B12: Environment | C12: iParque - Multimodal robotic sensor dataset in a forest scenario. Trajectory recording, perception, and localization for robotic research. | D12: Contains synchronized multi-sensor recordings (LiDAR, stereo + RGB-D cameras, IMU, GNSS) | E12: Zenodo | F12: https://zenodo.org/records/13757084 | G12: 1 | I12: 1 | J12: 1 | K12: 1 | L12: 1 | M12: 1 | N12: 1
A13: 11 | B13: Mobile | C13: Raw GNSS and multi-sensor dataset from Android devices | D13: Data collected with an Android app called Mimir (and GNSSLogger for some sessions), across five devices | E13: Zenodo | F13: https://zenodo.org/records/8340005 | G13: 1 | I13: 1 | J13: 1 | K13: 1 | L13: 1 | M13: 1 | N13: 1
A14: 12 | B14: Health | C14: Tactile sensing of human hand during activities of daily living (ADL) | D14: raw & interpolated pressure values, grip force, contribution of 18 sensing regions, synchronization indices among subjects | E14: Zenodo | F14: https://zenodo.org/records/4607289 | G14: 1 | H14: 1 | I14: 1 | J14: 1 | K14: 1 | L14: 1 | N14: 1
A15: 13 | B15: Manufacturing | C15: Driving posture recognition using pressure sensors | D15: 30 healthy adults with varying BMI, height, weight, 20 distinct driving postures | E15: Zenodo | F15: https://zenodo.org/records/15199100 | G15: 1 | H15: 1 | I15: 1 | J15: 1 | K15: 1
A16: 14 | B16: Environment | C16: UAV telemetry dataset with labeled states and environmental factors | D16: The dataset is directly collected from drone-integrated sensors (IMU, GNSS, flight controller) and an external TriSonica Mini weather sensor. | E16: Zenodo | F16: https://zenodo.org/records/13682870 | G16: 1 | I16: 1 | J16: 1 | K16: 1 | N16: 1
A17: 15 | B17: Agriculture | C17: Monitoring cotton crop growth and field conditions, combining sowing, acreage, geolocation, and sensor-based data for agricultural decision-making | D17: Includes crop details (type, sowing date, acreage, location, coordinates, monitoring date, device ID) | E17: Zenodo | F17: https://zenodo.org/records/8371502 | G17: 1 | H17: 1 | I17: 1 | J17: 1 | K17: 1 | M17: 1 | N17: 1
A18: 16 | B18: Robotics | C18: Landing maneuvers of a bioinspired ornithopter | D18: Data was collected from simulated onboard sensors during bioinspired landing maneuvers. | E18: Zenodo | F18: https://zenodo.org/records/3930442 | G18: 1 | H18: 1 | I18: 1 | J18: 1 | K18: 1 | M18: 1 | N18: 1
A19: 17 | B19: Animal | C19: Standardized benchmark for evaluating behavior classification models from multi-sensor datasets | D19: Onboard wearable sensors and animal-borne sensors (e.g., accelerometers, gyroscopes) used to capture behavior/activity signals | E19: Zenodo | F19: https://zenodo.org/records/10982620 | G19: 1 | H19: 1 | I19: 1 | J19: 1 | K19: 1 | N19: 1
A20: 18 | B20: Agriculture | C20: Multi-modal monitoring of honeybee colonies with environmental sensors and phenotypic trait | D20: Includes temperature, humidity, and acoustic features from sensors placed in beehives. | E20: Zenodo | F20: https://zenodo.org/records/11398835 | G20: 1 | H20: 1 | I20: 1 | J20: 1 | K20: 1 | M20: 1 | N20: 1
A21: 19 | B21: Environment | C21: Temperature-modulated metal-oxide gas sensing | D21: VOC concentrations (ppb), humidity, CO, H₂, TVOCs (ppb + µg/m³), and timestamps | E21: Zenodo | F21: https://zenodo.org/records/4593853 | G21: 1 | H21: 1 | I21: 1 | J21: 1 | K21: 1 | N21: 1
A22: 20 | B22: Mobile | C22: Multimodal sensor dataset for GNSS-based positioning and context detection | D22: GNSS raw measurements & position fixes, Accelerometer, Gyroscope, Magnetometer, Barometer, Step counter / step detector | E22: Zenodo | F22: https://zenodo.org/records/12566912 | G22: 1 | H22: 1 | I22: 1 | J22: 1 | K22: 1 | L22: 1 | M22: 1 | N22: 1
A23: 21 | B23: Health | C23: Remote patient monitoring | D23: The dataset was collected using wearable and ambient IoT sensors (acceleration, heart rate, motion, position, sleep, steps) | E23: Zenodo | F23: https://zenodo.org/records/14911563 | G23: 1 | H23: 1 | I23: 1 | J23: 1 | K23: 1 | M23: 1 | N23: 1
A24: 22 | B24: Robotics | C24: Multisensor benchmarking dataset for image recognition | D24: It uses imaging IoT sensors (hyperspectral camera, Kinect depth sensor, HD camera on a mobile robotic chassis) to capture multimodal data (images, spectra, and 3D point clouds) | E24: Zenodo | F24: https://zenodo.org/records/4010348 | G24: 1 | H24: 1 | I24: 1 | J24: 1 | K24: 1 | L24: 1
A25: 23 | B25: Robotics | C25: Sequential human-to-human object handovers in shelving and unshelving tasks | D25: Includes multimodal recordings: RGB video, depth maps, 3D motion capture (bones + markers), and anthropometric measurements. | E25: Zenodo | F25: https://zenodo.org/records/7895500 | G25: 1 | H25: 1 | I25: 1 | J25: 1 | K25: 1 | L25: 1 | M25: 1 | N25: 1
A26: 24 | B26: Smart Cities | C26: Quantitative evaluation of urban behavioral changes after a disaster event (2015 Paris terrorist attacks) | D26: Permanent traffic sensors installed on the Paris city road network | E26: Zenodo | F26: https://zenodo.org/records/819905 | G26: 1 | I26: 1 | J26: 1 | K26: 1 | L26: 1 | N26: 1
A27: 25 | B27: Robotics | C27: Multimodal dataset for fusion of sonar and camera data to improve obstacle detection and navigation in AUVs | D27: It uses underwater IoT sensing devices: a forward-looking sonar (FLS), forward-looking camera (FLC), and navigation sensors (GPS, DVL, IMU) | E27: Zenodo | F27: https://zenodo.org/records/10544811 | G27: 1 | I27: 1 | J27: 1 | K27: 1 | M27: 1 | N27: 1
A28: 26 | B28: Robotics | C28: Dataset for robot navigation and perception using multimodal sensors | D28: It uses robot-mounted IoT sensors (LiDAR, IMU, RGB camera) integrated into the Unitree Go1 quadruped robot platform | E28: Zenodo | F28: https://zenodo.org/records/13754606 | G28: 1 | I28: 1 | J28: 1 | K28: 1 | L28: 1 | M28: 1 | N28: 1
A29: 27 | B29: Robotics | C29: Obstacle detection and navigation in tropical underwater environments | D29: It uses underwater IoT sensors (forward-looking camera, forward-looking sonar, depth sensor) mounted on the Blue-ROV2 | E29: Zenodo | F29: https://zenodo.org/records/12093143 | G29: 1 | I29: 1 | J29: 1 | K29: 1 | M29: 1 | N29: 1
A30: 28 | B30: Robotics | C30: Dataset for multimodal robot perception using LiDAR, IMU, and camera streams | D30: Dataset for multimodal robot perception using LiDAR, IMU, and camera streams | E30: Zenodo | F30: https://zenodo.org/records/13754446 | G30: 1 | I30: 1 | J30: 1 | K30: 1 | N30: 1
A31: 29 | B31: Robotics | C31: Dataset for localisation and positioning under challenging conditions | D31: It uses multiple wearable and body-mounted IoT sensors (GNSS, IMU, stereo camera, PERSY foot-mounted system) to record positioning and movement data | E31: Zenodo | F31: https://zenodo.org/records/4290789 | G31: 1 | I31: 1 | J31: 1 | K31: 1 | M31: 1 | N31: 1
A32: 30 | B32: Manufacturing | C32: Dataset for analysing thermal effects and structural deformations in a large-scale CNC machining centre | D32: It integrates structural IoT sensors (IDS bars, thermocouples) and embedded CNC machine sensors (positions, loads, power, temperatures) | E32: Zenodo | F32: https://zenodo.org/records/16579804 | G32: 1 | I32: 1 | J32: 1 | K32: 1 | N32: 1
A33: 31 | B33: Robotics | C33: An annotated underwater pipeline inspection dataset | D33: It uses IoT-enabled sensing on an AUV, including cameras, side-scan sonar, and inertial navigation sensors | E33: Zenodo | F33: https://zenodo.org/records/12666132 | G33: 1 | I33: 1 | J33: 1 | K33: 1 | N33: 1
A34: 32 | B34: Public Safety | C34: Life-sign detection (breathing rate) behind walls using UWB radar | D34: Includes human presence (standing, lying) and no-human control sessions | E34: Zenodo | F34: https://zenodo.org/records/10779256 | G34: 1 | I34: 1 | J34: 1 | K34: 1 | M34: 1 | N34: 1
A35: 33 | B35: Physics | C35: Experimental validation of a gravity propulsion engine within the Simplified Theory of Everything (STOE) and Gluon Orbit Theory | D35: Real-time physical measurements from a USB optical sensor, combined with AI-based signal interpretation and simulation outputs | E35: Zenodo | F35: https://zenodo.org/records/15569226 | G35: 1 | I35: 1 | J35: 1 | K35: 1 | N35: 1
A36: 34 | B36: Environment | C36: Long-term marine IoT dataset for environmental monitoring and IoT system security | D36: Includes environmental data + operational/communication metrics + spoofing labels for security research | E36: Zenodo | F36: https://zenodo.org/records/15553598 | G36: 1 | I36: 1 | J36: 1 | K36: 1 | N36: 1
A37: 35 | B37: Transportation | C37: Magnetic field signals from vehicles entering/exiting a facility | D37: It uses a spintronic magnetic field sensor deployed at an entrance gate to capture real-world vehicle passage signals | E37: Zenodo | F37: https://zenodo.org/records/15475624 | G37: 1 | I37: 1 | J37: 1 | K37: 1 | N37: 1
A38: 36 | B38: Health | C38: Human behaviour analysis from multimodal inertial wearables; activity recognition (standing, walking, stand→sit) and fall-detection benchmarking | D38: Captured by wearable Shimmer3 inertial sensors (accelerometer + gyroscope) mounted at the waist, logging at 50 Hz with timestamped readings | E38: Harvard Dataverse | F38: https://dataverse.harvard.edu/dataset.xhtml?persistentId=doi:10.7910/DVN/6CKENX | G38: 1 | H38: 1 | I38: 1 | J38: 1 | K38: 1 | L38: 1 | M38: 1 | N38: 1
A39: 37 | B39: Health | C39: Sign language recognition dataset — gestures corresponding to 26 alphabet letters (A–Z) and 10 digits (1–10) | D39: Using 5 flex sensors connected to an Arduino ATMega microcontroller, producing digitised signals (0–1023) | E39: Harvard Dataverse | F39: https://dataverse.harvard.edu/dataset.xhtml?persistentId=doi:10.7910/DVN/ODY7GH | G39: 1 | H39: 1 | I39: 1 | J39: 1 | K39: 1 | N39: 1
A40: 38 | B40: Transportation | C40: Detection and classification of rash driving patterns using smartphone IMU signals | D40: Data was collected by a smartphone’s built-in IMU sensors (accelerometer + gyroscope) running the Sensor Logger Android app, which qualifies as an IoT data source | E40: Open Science Framework | F40: https://osf.io/4g87c/ | G40: 1 | H40: 1 | I40: 1 | J40: 1 | K40: 1 | L40: 1 | M40: 1 | N40: 1
...

Sheet Analysis
A1: Row Labels | B1: Count of Topic
A2: Aerospace | B2: 1
A3: Animal | B3: 1
A4: Physics | B4: 1
A5: Smart Cities | B5: 1
A6: Public Safety | B6: 1
A7: Transportation | B7: 2
A8: Mobile | B8: 2
A9: Engineering | B9: 2
A10: Manufacturing | B10: 2
A11: Communication | B11: 3
A12: Agriculture | B12: 4
A13: Health | B13: 9
... A16: Grand Total | B16: 69
A28: Component | B28: Dataset Count | C28: Percentage
A29: IoT Device | B29: 69 | C29: =Table1[[#This Row],[Dataset Count]]/GETPIVOTDATA("Topic",$A$1) -> 1
A30: FeatureOfInterest | B30: 69 | C30: =Table1[[#This Row],[Dataset Count]]/GETPIVOTDATA("Topic",$A$1) -> 1
A31: Property | B31: 69 | C31: =Table1[[#This Row],[Dataset Count]]/GETPIVOTDATA("Topic",$A$1) -> 1
A32: Result | B32: 69 | C32: =Table1[[#This Row],[Dataset Count]]/GETPIVOTDATA("Topic",$A$1) -> 1
A33: resultTime | B33: 67 | C33: =Table1[[#This Row],[Dataset Count]]/GETPIVOTDATA("Topic",$A$1) -> 0.97101449
A34: Deployment | B34: 45 | C34: =Table1[[#This Row],[Dataset Count]]/GETPIVOTDATA("Topic",$A$1) -> 0.65217391
A35: Sample | B35: 33 | C35: =Table1[[#This Row],[Dataset Count]]/GETPIVOTDATA("Topic",$A$1) -> 0.47826087
A36: Platform | B36: 16 | C36: =Table1[[#This Row],[Dataset Count]]/GETPIVOTDATA("Topic",$A$1) -> 0.23188406
